2023-05-03 08:12:00,810 INFO    MainThread:3728 [wandb_setup.py:_flush():76] Current SDK version is 0.15.1
2023-05-03 08:12:00,810 INFO    MainThread:3728 [wandb_setup.py:_flush():76] Configure stats pid to 3728
2023-05-03 08:12:00,810 INFO    MainThread:3728 [wandb_setup.py:_flush():76] Loading settings from C:\Users\kalyan\.config\wandb\settings
2023-05-03 08:12:00,810 INFO    MainThread:3728 [wandb_setup.py:_flush():76] Loading settings from E:\FedCMA-ktboi\code\wandb\settings
2023-05-03 08:12:00,810 INFO    MainThread:3728 [wandb_setup.py:_flush():76] Loading settings from environment variables: {}
2023-05-03 08:12:00,810 INFO    MainThread:3728 [wandb_setup.py:_flush():76] Applying setup settings: {'_disable_service': False}
2023-05-03 08:12:00,810 INFO    MainThread:3728 [wandb_setup.py:_flush():76] Inferring run settings from compute environment: {'program_relpath': 'main_full.py', 'program': 'E:\\FedCMA-ktboi\\code\\main_full.py'}
2023-05-03 08:12:00,810 INFO    MainThread:3728 [wandb_init.py:_log_setup():507] Logging user logs to E:\FedCMA-ktboi\code\wandb\run-20230503_081200-ymu2q258\logs\debug.log
2023-05-03 08:12:00,810 INFO    MainThread:3728 [wandb_init.py:_log_setup():508] Logging internal logs to E:\FedCMA-ktboi\code\wandb\run-20230503_081200-ymu2q258\logs\debug-internal.log
2023-05-03 08:12:00,810 INFO    MainThread:3728 [wandb_init.py:init():547] calling init triggers
2023-05-03 08:12:00,810 INFO    MainThread:3728 [wandb_init.py:init():554] wandb.init called with sweep_config: {}
config: {'gitlog': ' ', 'net': 'lenet', 'use_sigmoid': 'relu', 'data_path': '~/data/CIFAR10', 'logdir': './logs\\2023-05-03-08-11-59_lenet-84_2_0_0.1-0.0005-none-1.0-0.9-none-1.0-0.9-none-128_none_relu_50', 'group_name': 'group', 'project': 'project', 'embedding_dim': 84, 'data_seed': 0, 'seed': 0, 'num_workers': 2, 'dirichlet': False, 'alpha': 0.1, 'lr': 0.1, 'lr_scheduler': 'none', 'lr_gamma': 1.0, 'lr_alpha': 0.9, 'lr_decay': 'none', 'lrl2_gamma': 1.0, 'lrl2_alpha': 0.9, 'lrl2_decay': 'none', 'weight_decay': 0.0005, 'per_layer_lr': False, 'batch_size': 128, 'lamda': 0.5, 'lamda_l2': 0.5, 'num_epochs': 50, 'use_transfer_until': 50, 'use_weight_transfer_after': 0, 'normalize': False, 'mean_computation_dataset': 'train-subset', 'mean_computation_batch_size': 128, 'shuffle': 'False', 'share_last_layer': False, 'weighted_sharing': False, 'hetero_arch': False, 'active_ratio': 1.0, 'transfer': 'none', 'num_moments': 1, 'compute_divergence': False, 'discr_comp_interval': 50, 'resume': False}
2023-05-03 08:12:00,810 INFO    MainThread:3728 [wandb_init.py:init():596] starting backend
2023-05-03 08:12:00,810 INFO    MainThread:3728 [wandb_init.py:init():600] setting up manager
2023-05-03 08:12:00,822 INFO    MainThread:3728 [wandb_init.py:init():606] backend started and connected
2023-05-03 08:12:00,830 INFO    MainThread:3728 [wandb_init.py:init():700] updated telemetry
2023-05-03 08:12:00,830 INFO    MainThread:3728 [wandb_init.py:init():737] communicating run to backend with 60.0 second timeout
2023-05-03 08:12:01,090 ERROR   MainThread:3728 [wandb_init.py:init():763] encountered error: It appears that you do not have permission to access the requested resource. Please reach out to the project owner to grant you access. If you have the correct permissions, verify that there are no issues with your networking setup.(Error 403: Forbidden)
2023-05-03 08:12:01,406 ERROR   MainThread:3728 [wandb_init.py:init():1168] It appears that you do not have permission to access the requested resource. Please reach out to the project owner to grant you access. If you have the correct permissions, verify that there are no issues with your networking setup.(Error 403: Forbidden)
Traceback (most recent call last):
  File "C:\Users\kalyan\anaconda3\envs\fedlr1\lib\site-packages\wandb\sdk\wandb_init.py", line 1150, in init
    run = wi.init()
  File "C:\Users\kalyan\anaconda3\envs\fedlr1\lib\site-packages\wandb\sdk\wandb_init.py", line 769, in init
    raise error
wandb.errors.CommError: It appears that you do not have permission to access the requested resource. Please reach out to the project owner to grant you access. If you have the correct permissions, verify that there are no issues with your networking setup.(Error 403: Forbidden)
2023-05-03 08:12:02,414 WARNING MsgRouterThr:3728 [router.py:message_loop():77] message_loop has been closed
