2023-05-03 08:08:29,898 INFO    StreamThr :11776 [internal.py:wandb_internal():86] W&B internal server running at pid: 11776, started at: 2023-05-03 08:08:29.898530
2023-05-03 08:08:29,898 DEBUG   HandlerThread:11776 [handler.py:handle_request():144] handle_request: status
2023-05-03 08:08:29,910 INFO    WriterThread:11776 [datastore.py:open_for_write():85] open: E:\FedCMA\code\wandb\run-20230503_080829-mf68q4tl\run-mf68q4tl.wandb
2023-05-03 08:08:29,910 DEBUG   SenderThread:11776 [sender.py:send():375] send: header
2023-05-03 08:08:29,910 DEBUG   SenderThread:11776 [sender.py:send():375] send: run
2023-05-03 08:08:30,194 ERROR   SenderThread:11776 [internal_api.py:execute():288] 403 response executing GraphQL.
2023-05-03 08:08:30,194 ERROR   SenderThread:11776 [internal_api.py:execute():289] {"errors":[{"message":"permission denied","path":["upsertBucket"],"extensions":{"code":"PERMISSION_ERROR"}}],"data":{"upsertBucket":null}}
2023-05-03 08:08:30,194 ERROR   SenderThread:11776 [sender.py:send_run():979] It appears that you do not have permission to access the requested resource. Please reach out to the project owner to grant you access. If you have the correct permissions, verify that there are no issues with your networking setup.(Error 403: Forbidden)
Traceback (most recent call last):
  File "C:\Users\kalyan\anaconda3\envs\fedlr1\lib\site-packages\wandb\sdk\lib\retry.py", line 131, in __call__
    result = self._call_fn(*args, **kwargs)
  File "C:\Users\kalyan\anaconda3\envs\fedlr1\lib\site-packages\wandb\sdk\internal\internal_api.py", line 285, in execute
    return self.client.execute(*args, **kwargs)  # type: ignore
  File "C:\Users\kalyan\anaconda3\envs\fedlr1\lib\site-packages\wandb\vendor\gql-0.2.0\wandb_gql\client.py", line 52, in execute
    result = self._get_result(document, *args, **kwargs)
  File "C:\Users\kalyan\anaconda3\envs\fedlr1\lib\site-packages\wandb\vendor\gql-0.2.0\wandb_gql\client.py", line 60, in _get_result
    return self.transport.execute(document, *args, **kwargs)
  File "C:\Users\kalyan\anaconda3\envs\fedlr1\lib\site-packages\wandb\sdk\lib\gql_request.py", line 56, in execute
    request.raise_for_status()
  File "C:\Users\kalyan\anaconda3\envs\fedlr1\lib\site-packages\requests\models.py", line 1021, in raise_for_status
    raise HTTPError(http_error_msg, response=self)
requests.exceptions.HTTPError: 403 Client Error: Forbidden for url: https://api.wandb.ai/graphql

During handling of the above exception, another exception occurred:

Traceback (most recent call last):
  File "C:\Users\kalyan\anaconda3\envs\fedlr1\lib\site-packages\wandb\sdk\internal\sender.py", line 977, in send_run
    self._init_run(run, config_value_dict)
  File "C:\Users\kalyan\anaconda3\envs\fedlr1\lib\site-packages\wandb\sdk\internal\sender.py", line 1015, in _init_run
    server_run, inserted, server_messages = self._api.upsert_run(
  File "C:\Users\kalyan\anaconda3\envs\fedlr1\lib\site-packages\wandb\apis\normalize.py", line 73, in wrapper
    raise err
  File "C:\Users\kalyan\anaconda3\envs\fedlr1\lib\site-packages\wandb\apis\normalize.py", line 41, in wrapper
    return func(*args, **kwargs)
  File "C:\Users\kalyan\anaconda3\envs\fedlr1\lib\site-packages\wandb\sdk\internal\internal_api.py", line 1690, in upsert_run
    response = self.gql(
  File "C:\Users\kalyan\anaconda3\envs\fedlr1\lib\site-packages\wandb\sdk\internal\internal_api.py", line 257, in gql
    ret = self._retry_gql(
  File "C:\Users\kalyan\anaconda3\envs\fedlr1\lib\site-packages\wandb\sdk\lib\retry.py", line 147, in __call__
    retry_timedelta_triggered = check_retry_fn(e)
  File "C:\Users\kalyan\anaconda3\envs\fedlr1\lib\site-packages\wandb\util.py", line 907, in check_retry_fn
    return fallback_retry_fn(e)
  File "C:\Users\kalyan\anaconda3\envs\fedlr1\lib\site-packages\wandb\util.py", line 849, in no_retry_auth
    raise CommError(
wandb.errors.CommError: It appears that you do not have permission to access the requested resource. Please reach out to the project owner to grant you access. If you have the correct permissions, verify that there are no issues with your networking setup.(Error 403: Forbidden)
2023-05-03 08:08:30,346 DEBUG   HandlerThread:11776 [handler.py:handle_request():144] handle_request: shutdown
2023-05-03 08:08:30,346 INFO    HandlerThread:11776 [handler.py:finish():845] shutting down handler
2023-05-03 08:08:30,911 INFO    WriterThread:11776 [datastore.py:close():298] close: E:\FedCMA\code\wandb\run-20230503_080829-mf68q4tl\run-mf68q4tl.wandb
2023-05-03 08:08:31,203 INFO    SenderThread:11776 [sender.py:finish():1550] shutting down sender
